Workbook

Sheet À faire ce mois
A1: À FAIRE / À SURVEILLER
A2: Vue dynamique : cette feuille se met à jour automatiquement selon la date du jour. Elle affiche les retards, les échéances ≤ 30 jours et les déclenchements conditionnels à surveiller.
A3: 🔴 En retard • 🟠 À déclencher • 🟡 À préparer • 🟢 À jour • ⚪ À surveiller / qualifier
A4: Convention | B4: Service | C4: Responsable | D4: Échéance / déclencheur | E4: Alerte | F4: Action
A5: {=_xlfn._xlws.FILTER('Suivi simple'!$C$5:$C$235,(('Suivi simple'!$N$5:$N$235="🔴 En retard")+('Suivi simple'!$N$5:$N$235="🟠 À déclencher")+('Suivi simple'!$N$5:$N$235="⚪ À surveiller")),"")} -> اتفاقیة شراكة متعلقة بالمساھمة في تنظیم تغازوت سورف اكسبو | B5: {=_xlfn._xlws.FILTER('Suivi simple'!#REF!,(('Suivi simple'!$N$5:$N$235="🔴 En retard")+('Suivi simple'!$N$5:$N$235="🟠 À déclencher")+('Suivi simple'!$N$5:$N$235="⚪ À surveiller")),"")} -> #REF! | C5: {=_xlfn._xlws.FILTER('Suivi simple'!#REF!,(('Suivi simple'!$N$5:$N$235="🔴 En retard")+('Suivi simple'!$N$5:$N$235="🟠 À déclencher")+('Suivi simple'!$N$5:$N$235="⚪ À surveiller")),"")} -> #REF! | D5: {=_xlfn._xlws.FILTER('Suivi simple'!$L$5:$L$235,(('Suivi simple'!$N$5:$N$235="🔴 En retard")+('Suivi simple'!$N$5:$N$235="🟠 À déclencher")+('Suivi simple'!$N$5:$N$235="⚪ À surveiller")),"")} -> 46197 | E5: {=_xlfn._xlws.FILTER('Suivi simple'!$N$5:$N$235,(('Suivi simple'!$N$5:$N$235="🔴 En retard")+('Suivi simple'!$N$5:$N$235="🟠 À déclencher")+('Suivi simple'!$N$5:$N$235="⚪ À surveiller")),"")} -> 🔴 En retard | F5: {=_xlfn._xlws.FILTER('Suivi simple'!$T$5:$T$235,(('Suivi simple'!$N$5:$N$235="🔴 En retard")+('Suivi simple'!$N$5:$N$235="🟠 À déclencher")+('Suivi simple'!$N$5:$N$235="⚪ À surveiller")),"")} -> Organiser / régulariser
A6: اتفاقیة شراكة من أجل الترویج السیاحي لجھة سوس ماسة | D6: 46176 | E6: 🔴 En retard | F6: Organiser / régulariser
A7: اتفاقیة شراكة متعلقة بتجدید وإعادة تأھیل الوحدات الفندقیة | D7: 46204 | E7: 🔴 En retard | F7: Organiser / régulariser
A8: اتفاقیة شراكة من اجل تكلیف شركة التنمیة السیاحیة لسوس ماسة بانجاز الدراسات واالشغال المتعلقة بتنمیة القطاع السیاحي خصوصا في المناطق الخلفیة لجھة سوس ماسة | D8: 46204 | E8: 🔴 En retard | F8: Organiser / régulariser
A9: اتفاقیة الشراكة المتعلقة بتكلیف شركة التنمیة الجھویة "التنمیة السیاحیة لسوس ماسة " بإنجاز الدراسات و االشغال المتعلقة بتنمبة القطاع السیاحي خصوصا في المناطق الخلفیة لجھة سوس ماسة | D9: 46204 | E9: 🔴 En retard | F9: Organiser / régulariser
A10: اتفاقیة شراكة متعلقة بتھیئة منطقة مخصصة الستقبال االستثمارات بجماعة امسوان | D10: 46204 | E10: 🔴 En retard | F10: Organiser / régulariser
A11: اتفاقیة الشراكة المتعلقة بتھیئة "نقطة أنشور بتغازوت الستقبال االستثمارات السیاحیة " | D11: 46204 | E11: 🔴 En retard | F11: Organiser / régulariser
A12: اتفاقیة شراكة من اجل تھیئة كورنیش تغازوت | D12: 46204 | E12: 🔴 En retard | F12: Organiser / régulariser
A13: اتفاقیة شراكة بین وزارة السیاحة و الصناعة التقلیدیة و االقتصاد االجتماعي و التضامني و جھة سوس ماسة و المجالس اإلقلیمیة للسیاحة بالجھة | D13: 46266 | E13: 🔴 En retard | F13: Organiser / régulariser
A14: اتفاقیة الشراكة بین جھة سوس ماسة والجامعة الملكیة المغربیة لركوب االمواج | D14: 46268 | E14: 🔴 En retard | F14: Organiser / régulariser
A15: اتفاقیة شراكة بین جھة سوس ماسة وجمعیة التكنولوجیا الزراعیة لسوس ماسة | D15: 0 | E15: ⚪ À surveiller | F15: Vérifier le déclencheur
A16: اتفاقیة شراكة من أجل تمویل مشاریع البحث العلمي بقطاع البستنة تماشیا مع التوجھات االستراتیجیة لمجلس جھة سوس ماسة في تدبیر الماء | D16: 2027 | E16: ⚪ À surveiller | F16: Vérifier le déclencheur
A17: مشروع إتفاقیة شراكة بین جھة سوس ماسة وجمعیة أكادیر ألیوبول؛ | D17: 46163 | E17: 🔴 En retard | F17: Organiser / régulariser
A18: اتفاقیة شراكة إلنشاء مشاریع تربیة األحیاء البحریة مع مجموعة الشباب المقاول "شركة اكوا مول" | D18: سیتم برمجة االجتماع بعد التوصل بتقریر حول حالة تقدم المشروع | E18: ⚪ À surveiller | F18: Vérifier le déclencheur
A19: اتفاقیة شراكة إلنشاء مشاریع تربیة األحیاء البحریة مع مجموعة الشباب المقاول "شركة بلو ھارفست"؛ | D19: سیتم برمجة االجتماع بعد التوصل بتقریر حول حالة تقدم المشروع | E19: ⚪ À surveiller | F19: Vérifier le déclencheur
A20: اتفاقیة شراكة القتناء وتجھیز منصة عائمة لتعبئة و تثمین منتوجات تربیة األحیاء البحریة بین جھة سوس ماسة و الوكالة الوطنیة لتنمیة تربیة األحیاء البحریة وتعاونیة أكواكول سوس ماسة | D20: سیتم برمجة االجتماع بعد التوصل بتقریر حول حالة تقدم المشروع | E20: ⚪ À surveiller | F20: Vérifier le déclencheur
A21: اتفاقیة شراكة بین جھة سوس ماسة ، الوكالة الوطنیة لتنمیة تربیة االحیاء البحریة وشركة لفیكتوار سیفود | D21: سیتم برمجة االجتماع بعد التوصل بتقریر حول حالة تقدم المشروع | E21: ⚪ À surveiller | F21: Vérifier le déclencheur
A22: اتفاقیة شراكة بین جھة سوس ماسة ، الوكالة الوطنیة لتنمیة تربیة االحیاء البحریة وشركة كباكوا | D22: سیتم برمجة االجتماع بعد التوصل بتقریر حول حالة تقدم المشروع | E22: ⚪ À surveiller | F22: Vérifier le déclencheur
A23: اتفاقیة شراكة من أجل تھیئة قطب لتثمین منتوجات االحیاء البحریة -اكوابول تیغرت - في منطقة تیغرت – ایمي ودار | D23: 46295 | E23: 🟠 À déclencher | F23: Préparer la convocation
A24: اتفاقیة شراكة بین الجھة و جمعیة لوجیبول سوس ماسة | D24: 46295 | E24: 🟠 À déclencher | F24: Préparer la convocation
A25: اتفاقیة شراكة حول إحداث تیكنوبارك بمدینة تیزنیت | D25: في انتظار برمجة اجتماع من طرف جماعة تزنیت باعتبارھا رئیسة لجنة التتبع | E25: ⚪ À surveiller | F25: Vérifier le déclencheur
A26: اتفاقیة شراكة من اجل دعم تدبیر واستغالل تكنوبارك اكادیر | D26: االربعاء 08 یولیوز 2026 | E26: ⚪ À surveiller | F26: Vérifier le déclencheur
A27: اتفاقیة شراكة من اجل احداث وتدبیر مركز لتكوین الشباب في مجال JADARA البرمجة الرقمیة بجھة سوس ماسة | D27: الخمیس 09 یولیوز 2026 | E27: ⚪ À surveiller | F27: Vérifier le déclencheur
A28: اتفاقیة شراكة من أجل دعم تدبیر و تنشیط مدینة االبتكار سوس ماسة | D28: الجمعة 10 یولیوز 2026 | E28: ⚪ À surveiller | F28: Vérifier le déclencheur
A29: اتفاقیة شراكة من أجل دعم تكوین و ادماج الشباب في مجل مھن School Digital - الرقمنة بجھة سوس ماسة | D29: تمت مراسلة السید الوالي من اجل برمجة اجتماع لجنة التتبع ارسالیة عدد 842 بتاریخ 10 یونیو 2026 | E29: ⚪ À surveiller | F29: Vérifier le déclencheur
A30: اتفاقیة شراكة خاصة بتجھیز واستغالل وتدبیر تكنوبارك تیزنیت | D30: في انتظار توقیع االتفاقیة من طرف وزارة االنتقال الرقمي و اصالح االدارة | E30: ⚪ À surveiller | F30: Vérifier le déclencheur
A31: اتفاقیة اطار الشراكة لتعزیز البحث العلمي و التكوین واالبتكار في مجال تدبیر الموارد المائیة | D31: في انتظار استكمال التوقیعات من طرف باقي االطراف | E31: ⚪ À surveiller | F31: Vérifier le déclencheur
A32: اتفاقیة شراكة وتعاون مع جمعیة مبادرة سوس ماسة | D32: -09-2026 21 | E32: ⚪ À surveiller | F32: Vérifier le déclencheur
A33: اتفاقیة شراكة الحداث منطقة االنشطة االقتصادیة بمدینة طاطا | D33: مراسلة السید الوالي | E33: ⚪ À surveiller | F33: Vérifier le déclencheur
A34: اتفاقیة شراكة النجاز محطة تصفیة المیاه العادمة بالمنطقة الصناعیة اوالد تایمة | D34: مراسلة السید العامل | E34: ⚪ À surveiller | F34: Vérifier le déclencheur
A35: اتفاقیة شراكة من اجل دعم االستثمار بجھة سوس ماسة في إطار مخطط التسریع الصناعي لفائدة شركة "VETCAM" | D35: 0 | E35: ⚪ À surveiller | F35: Vérifier le déclencheur
A36: اتفاقیة شراكة من اجل انجاز برنامج دعم الشباب لخلق وتطویر انشطة مقاوالتیة صغیرة جدا بجھة سوس ماسة TPE | D36: 46282 | E36: 🔴 En retard | F36: Organiser / régulariser
A37: اتفاقیة شراكة من اجل برنامج دعم الشباب لخلق وتطویر انشطة مدرة للدخل AGR | D37: 46282 | E37: 🔴 En retard | F37: Organiser / régulariser
A38: اتفاقیة شراكة متعلقة بالمساھمة في تمویل احداث وتفعیل الیة لدعم ومواكبة تسریع تطور المقاوالت السیاحیة الصغرى والمتوسطة والصغیرة جدا بجھة سوس ماسة | D38: 46281 | E38: 🔴 En retard | F38: Organiser / régulariser
A39: اتفاقیة اشراكة من اجل انجاز البرنامج الجھوي المندمج لمواكبة المقاوالت الصغیرة و الصغیرة جدا بجھة سوس ماسة ABRID | D39: 46273 | E39: 🔴 En retard | F39: Organiser / régulariser
A40: اتفاقیة الشراكة من أجل دعم التشغیل بمنظومة ترحیل الخدمات بجھة سوس ماسة لفائدة شركة سیكوال | D40: مراسلة السید الوالي | E40: ⚪ À surveiller | F40: Vérifier le déclencheur
...

Sheet Suivi simple
C1: SUIVI SIMPLE DES CONVENTIONS ET COMITÉS DE SUIVI
C2: Principe : 1 ligne = 1 convention. Mettre à jour seulement « Dernier comité » et « Responsable ». Les alertes indiquent la priorité d'action.
C3: Lecture rapide : 🔴 retard • 🟠 à déclencher • 🟡 à préparer • 🟢 à jour • ⚪ à surveiller / qualifier
A4: Rattachement | B4: Responsable du projet | C4: Convention visée | D4: Session | E4: Date de visa | F4: Présidence du comité | G4: Membres du comité | H4: Fréquence des réunions du comité | I4: Enveloppe Budgetaire | J4: Contribution de la Région | K4: Maitrise d'ouvrage | L4: Maitrise d'ouvrage délégué | M4: prochain comité | N4: Dernier comité | O4: PV | P4: Décision | Q4: Convention | R4: Fiche technique | S4: Statut de la convention | T4: Prochaine échéance | U4: Statut | V4: Nature des fonds | W4: FEC | X4: Programmation annuelle | Y4: montant engagé | Z4: montant versé | AA4: montant versé2 | AB4: Avancement des études | AC4: Avancement des travaux | AD4: Foncier | AE4: commentaire sur la pertinence
A5: direction division service | C5: اتفاقية شراكة مع قرية الاطفال المسعفين بأكادير لدعم تسيير قرية الاطفال المسعفين بأكادير من أجل تعزيز خدماتها الاجتماعية. | D5: année/SO | H5: - | N5: 45797 | P5: A renouveler/ A reconduire tacitemment / A maintenir/ A ne pas renouveler /A résilier | S5: En cours Arrivée à terme Résiliée | T5: 46231 | U5: TENUE/NON TENUE/A TENIR | V5: propres/FEC | W5: Contracté/pas encore | X5: 2026/2027/2027 | AB5: Finalisés/en cours/non entamé | AC5: Finalisés/en cours/non entamé | AD5: Assaini/non
C6: اتفاقية شراكة مع العصبة المغربية لحماية الطفولة للمساهمة في تسيير مركز للا آمنة للأطفال في وضعية صعبة بأيت ملول | H6: كلما دعت الضرورة إلى ذلك | N6: 46030 | T6: 46230 | U6: =IF(ISNUMBER(T6),IF(T6<TODAY(),"🔴 En retard",IF(T6<=TODAY()+30,"🟠 À déclencher",IF(T6<=TODAY()+60,"🟡 À préparer","🟢 À jour"))),IF(T6<>"","⚪ À surveiller",IF(OR(ISNUMBER(SEARCH("besoin",H6)),ISNUMBER(SEARCH("الضرورة",H6))),"⚪ À surveiller","⚪ À qualifier"))) -> 🔴 En retard | AB6: statut/taux | AC6: statut/taux
C7: اتفاقية شراكة من اجل بناء وتجهيز مركب اجتماعي- تربوي لفائدة الأطفال ذوي الاحتياجات الخاصة المحرومين من الأسر | H7: كلما دعت الضرورة إلى ذلك | N7: 45973 | T7: 46233 | U7: =IF(ISNUMBER(T7),IF(T7<TODAY(),"🔴 En retard",IF(T7<=TODAY()+30,"🟠 À déclencher",IF(T7<=TODAY()+60,"🟡 À préparer","🟢 À jour"))),IF(T7<>"","⚪ À surveiller",IF(OR(ISNUMBER(SEARCH("besoin",H7)),ISNUMBER(SEARCH("الضرورة",H7))),"⚪ À surveiller","⚪ À qualifier"))) -> 🔴 En retard
C8: اتفاقية شراكة بشأن برنامج توفير الدعم المالي واللوجستيكي للمركز الوطني محمد السادس للمعاقين -الملحقة الجهوية بأكادير" | H8: كلما دعت الضرورة إلى ذلك | U8: =IF(ISNUMBER(T8),IF(T8<TODAY(),"🔴 En retard",IF(T8<=TODAY()+30,"🟠 À déclencher",IF(T8<=TODAY()+60,"🟡 À préparer","🟢 À jour"))),IF(T8<>"","⚪ À surveiller",IF(OR(ISNUMBER(SEARCH("besoin",H8)),ISNUMBER(SEARCH("الضرورة",H8))),"⚪ À surveiller","⚪ À qualifier"))) -> ⚪ À surveiller
C9: اتفاقية شراكة من أجل بناء مساكن وظيفية لعناصر الدرك الملكي | H9: مرة كل ثلاثة أشهر على الأقل، وكلما دعــت الضرورة لذلك | N9: 46129 | T9: 46238 | U9: =IF(ISNUMBER(T9),IF(T9<TODAY(),"🔴 En retard",IF(T9<=TODAY()+30,"🟠 À déclencher",IF(T9<=TODAY()+60,"🟡 À préparer","🟢 À jour"))),IF(T9<>"","⚪ À surveiller",IF(OR(ISNUMBER(SEARCH("besoin",H9)),ISNUMBER(SEARCH("الضرورة",H9))),"⚪ À surveiller","⚪ À qualifier"))) -> 🔴 En retard
C10: اتفـــاقية شــراكـــةمن اجل تأهيل وتجهيز مؤسسة دار التكافل للأشخاص المسنين بايت ملول | H10: كلما دعت الضرورة إلى ذلك | N10: 46027 | U10: =IF(ISNUMBER(T10),IF(T10<TODAY(),"🔴 En retard",IF(T10<=TODAY()+30,"🟠 À déclencher",IF(T10<=TODAY()+60,"🟡 À préparer","🟢 À jour"))),IF(T10<>"","⚪ À surveiller",IF(OR(ISNUMBER(SEARCH("besoin",H10)),ISNUMBER(SEARCH("الضرورة",H10))),"⚪ À surveiller","⚪ À qualifier"))) -> ⚪ À surveiller
C11: اتفاقية شراكة لاقتناء سيارات النقل المدرسي بعمالات وأقاليم جهة سوس ماسة | H11: بصفة منتظمة، أو كلما دعت الضرورة إلى ذلك | N11: 45244 | T11: 46232 | U11: =IF(ISNUMBER(T11),IF(T11<TODAY(),"🔴 En retard",IF(T11<=TODAY()+30,"🟠 À déclencher",IF(T11<=TODAY()+60,"🟡 À préparer","🟢 À jour"))),IF(T11<>"","⚪ À surveiller",IF(OR(ISNUMBER(SEARCH("besoin",H11)),ISNUMBER(SEARCH("الضرورة",H11))),"⚪ À surveiller","⚪ À qualifier"))) -> 🔴 En retard
C12: اتفاقية شراكة من أجل بناء مرافق إدارية بإقامة الطالبة الجامعية باكادير | H12: كلما دعت الضرورة لذلك | N12: 46002 | T12: 46233 | U12: =IF(ISNUMBER(T12),IF(T12<TODAY(),"🔴 En retard",IF(T12<=TODAY()+30,"🟠 À déclencher",IF(T12<=TODAY()+60,"🟡 À préparer","🟢 À jour"))),IF(T12<>"","⚪ À surveiller",IF(OR(ISNUMBER(SEARCH("besoin",H12)),ISNUMBER(SEARCH("الضرورة",H12))),"⚪ À surveiller","⚪ À qualifier"))) -> 🔴 En retard
C13: اتفاقية شراكة مع جمعية إقامة الطالبة أكادير | H13: كلما دعت الضرورة إلى ذلك | T13: 46267 | U13: =IF(ISNUMBER(T13),IF(T13<TODAY(),"🔴 En retard",IF(T13<=TODAY()+30,"🟠 À déclencher",IF(T13<=TODAY()+60,"🟡 À préparer","🟢 À jour"))),IF(T13<>"","⚪ À surveiller",IF(OR(ISNUMBER(SEARCH("besoin",H13)),ISNUMBER(SEARCH("الضرورة",H13))),"⚪ À surveiller","⚪ À qualifier"))) -> 🔴 En retard
C14: اتفاقية شراكة من أجل تجهيز المركز الجهوي الاجتماعي والتربوي وشبه الطبي والمهني للأشخاص في وضعية إعاقة بالقليعة | H14: بصفة منتظمة وكلما دعت الضرورة إلى ذلك | N14: 46120 | T14: 46294 | U14: =IF(ISNUMBER(T14),IF(T14<TODAY(),"🔴 En retard",IF(T14<=TODAY()+30,"🟠 À déclencher",IF(T14<=TODAY()+60,"🟡 À préparer","🟢 À jour"))),IF(T14<>"","⚪ À surveiller",IF(OR(ISNUMBER(SEARCH("besoin",H14)),ISNUMBER(SEARCH("الضرورة",H14))),"⚪ À surveiller","⚪ À qualifier"))) -> 🟠 À déclencher
C15: اتفاقية شراكة مع مؤسسة للا سلمى للوقاية وعلاج السرطان لتمويل اقتناء أدوية ومواد صيدلية لعلاج السرطان | H15: Non précisé | U15: =IF(ISNUMBER(T15),IF(T15<TODAY(),"🔴 En retard",IF(T15<=TODAY()+30,"🟠 À déclencher",IF(T15<=TODAY()+60,"🟡 À préparer","🟢 À jour"))),IF(T15<>"","⚪ À surveiller",IF(OR(ISNUMBER(SEARCH("besoin",H15)),ISNUMBER(SEARCH("الضرورة",H15))),"⚪ À surveiller","⚪ À qualifier"))) -> ⚪ À qualifier
C16: اتفاقية شراكة مع جمعية عملية البسمة بالمغرب | H16: Non précisé | U16: =IF(ISNUMBER(T16),IF(T16<TODAY(),"🔴 En retard",IF(T16<=TODAY()+30,"🟠 À déclencher",IF(T16<=TODAY()+60,"🟡 À préparer","🟢 À jour"))),IF(T16<>"","⚪ À surveiller",IF(OR(ISNUMBER(SEARCH("besoin",H16)),ISNUMBER(SEARCH("الضرورة",H16))),"⚪ À surveiller","⚪ À qualifier"))) -> ⚪ À qualifier
C17: اتفاقية شراكة مع مؤسسة للا سلمى للوقاية وعلاج السرطان لتمويل اقتناء أدوية ومواد صيدلية لعلاج السرطان | H17: مرتين في السنة أو كلما دعت الضرورة إلى ذلك | T17: 46273 | U17: =IF(ISNUMBER(T17),IF(T17<TODAY(),"🔴 En retard",IF(T17<=TODAY()+30,"🟠 À déclencher",IF(T17<=TODAY()+60,"🟡 À préparer","🟢 À jour"))),IF(T17<>"","⚪ À surveiller",IF(OR(ISNUMBER(SEARCH("besoin",H17)),ISNUMBER(SEARCH("الضرورة",H17))),"⚪ À surveiller","⚪ À qualifier"))) -> 🔴 En retard
C18: اتفاقية شراكة مع جمعية عملية البسمة بالمغرب | H18: مرتين في السنة أو كلما دعت الضرورة إلى ذلك | T18: 46276 | U18: =IF(ISNUMBER(T18),IF(T18<TODAY(),"🔴 En retard",IF(T18<=TODAY()+30,"🟠 À déclencher",IF(T18<=TODAY()+60,"🟡 À préparer","🟢 À jour"))),IF(T18<>"","⚪ À surveiller",IF(OR(ISNUMBER(SEARCH("besoin",H18)),ISNUMBER(SEARCH("الضرورة",H18))),"⚪ À surveiller","⚪ À qualifier"))) -> 🔴 En retard
C19: اتفاقية الشراكة | H19: دورية الاجتماعات | U19: =IF(ISNUMBER(T19),IF(T19<TODAY(),"🔴 En retard",IF(T19<=TODAY()+30,"🟠 À déclencher",IF(T19<=TODAY()+60,"🟡 À préparer","🟢 À jour"))),IF(T19<>"","⚪ À surveiller",IF(OR(ISNUMBER(SEARCH("besoin",H19)),ISNUMBER(SEARCH("الضرورة",H19))),"⚪ À surveiller","⚪ À qualifier"))) -> ⚪ À qualifier
C20: اتفاقية شراكة من أجل احداث فضاء لتنشيط السياحي و الصناعة التقليدية بإداوكنيضيف | H20: مرة في كل 6 أشهر وكلما دعت الضرورة إلى ذلك, | U20: =IF(ISNUMBER(T20),IF(T20<TODAY(),"🔴 En retard",IF(T20<=TODAY()+30,"🟠 À déclencher",IF(T20<=TODAY()+60,"🟡 À préparer","🟢 À jour"))),IF(T20<>"","⚪ À surveiller",IF(OR(ISNUMBER(SEARCH("besoin",H20)),ISNUMBER(SEARCH("الضرورة",H20))),"⚪ À surveiller","⚪ À qualifier"))) -> ⚪ À surveiller
C21: اتفاقية شراكة إطار المتعلقة بمواكبة الفاعلين في قطاع الاقتصاد الاجتماعي و التضامني بالجهة | H21: مرة في كل ستة أشهر وكلما دعت الضرورة إلى دلك | N21: 45547 | T21: 46204 | U21: =IF(ISNUMBER(T21),IF(T21<TODAY(),"🔴 En retard",IF(T21<=TODAY()+30,"🟠 À déclencher",IF(T21<=TODAY()+60,"🟡 À préparer","🟢 À jour"))),IF(T21<>"","⚪ À surveiller",IF(OR(ISNUMBER(SEARCH("besoin",H21)),ISNUMBER(SEARCH("الضرورة",H21))),"⚪ À surveiller","⚪ À qualifier"))) -> 🔴 En retard
C22: اتفاقية شراكة خاصة متعلقة بالتمكين الاقتصادي للنساء بجهة سوس ماسة في قطاع الاقتصاد الاجتماعي و التضامني | H22: مرة كل ستة أشهر وكلما دعت الضرورة الى دلك. | N22: 45547 | T22: 46204 | U22: =IF(ISNUMBER(T22),IF(T22<TODAY(),"🔴 En retard",IF(T22<=TODAY()+30,"🟠 À déclencher",IF(T22<=TODAY()+60,"🟡 À préparer","🟢 À jour"))),IF(T22<>"","⚪ À surveiller",IF(OR(ISNUMBER(SEARCH("besoin",H22)),ISNUMBER(SEARCH("الضرورة",H22))),"⚪ À surveiller","⚪ À qualifier"))) -> 🔴 En retard
C23: اتفاقية شراكة من أجل تنظيم المعارض والأسواق المتنقلة لمنتوجات الاقتصاد الاجتماعي والتضامني | H23: مرة كل ستة أشهر وكلما دعت الضرورة الى دلك. | U23: =IF(ISNUMBER(T23),IF(T23<TODAY(),"🔴 En retard",IF(T23<=TODAY()+30,"🟠 À déclencher",IF(T23<=TODAY()+60,"🟡 À préparer","🟢 À jour"))),IF(T23<>"","⚪ À surveiller",IF(OR(ISNUMBER(SEARCH("besoin",H23)),ISNUMBER(SEARCH("الضرورة",H23))),"⚪ À surveiller","⚪ À qualifier"))) -> ⚪ À surveiller
C24: اتفاقية شراكة من أجل دعم التعاونيات التابعة لعمالات وأقاليم جهة سوس ماسة المنتقاة في إطار الجائزتين الوطنيتين "لالة المتعاونة"و"الجيل المتضامن" | H24: عند التهييء للجائزتين وكلما دعت الضرورة إلى دلك | N24: 46127 | U24: =IF(ISNUMBER(T24),IF(T24<TODAY(),"🔴 En retard",IF(T24<=TODAY()+30,"🟠 À déclencher",IF(T24<=TODAY()+60,"🟡 À préparer","🟢 À jour"))),IF(T24<>"","⚪ À surveiller",IF(OR(ISNUMBER(SEARCH("besoin",H24)),ISNUMBER(SEARCH("الضرورة",H24))),"⚪ À surveiller","⚪ À qualifier"))) -> ⚪ À surveiller
C25: اتفاقية شراكة من أجل تنظيم المعرض الدولي للمنتوجات المحلية بجهة سوس ماسة | H25: قبل تنظيم المعرض وكلما دعت الضرورة الى دلك | N25: 46167 | U25: =IF(ISNUMBER(T25),IF(T25<TODAY(),"🔴 En retard",IF(T25<=TODAY()+30,"🟠 À déclencher",IF(T25<=TODAY()+60,"🟡 À préparer","🟢 À jour"))),IF(T25<>"","⚪ À surveiller",IF(OR(ISNUMBER(SEARCH("besoin",H25)),ISNUMBER(SEARCH("الضرورة",H25))),"⚪ À surveiller","⚪ À qualifier"))) -> ⚪ À surveiller
C26: اتفاقية شراكة من أجل تنظيم المعارض الإقليمية للصناعة التقليدية بجهة سوس ماسة | H26: لتهيء كل المعارض الإقليمية ومواكبة تنظيمها | T26: 46204 | U26: =IF(ISNUMBER(T26),IF(T26<TODAY(),"🔴 En retard",IF(T26<=TODAY()+30,"🟠 À déclencher",IF(T26<=TODAY()+60,"🟡 À préparer","🟢 À jour"))),IF(T26<>"","⚪ À surveiller",IF(OR(ISNUMBER(SEARCH("besoin",H26)),ISNUMBER(SEARCH("الضرورة",H26))),"⚪ À surveiller","⚪ À qualifier"))) -> 🔴 En retard
C27: اتفاقية شراكة من أجل تنظيم المعرض الجهوي للصناعة التقليدية بجهة سوس ماسة | H27: لانتقاء العارضين ولتهيء المعرض الجهوي ومواكبة تنظيمه | N27: 45951 | U27: =IF(ISNUMBER(T27),IF(T27<TODAY(),"🔴 En retard",IF(T27<=TODAY()+30,"🟠 À déclencher",IF(T27<=TODAY()+60,"🟡 À préparer","🟢 À jour"))),IF(T27<>"","⚪ À surveiller",IF(OR(ISNUMBER(SEARCH("besoin",H27)),ISNUMBER(SEARCH("الضرورة",H27))),"⚪ À surveiller","⚪ À qualifier"))) -> ⚪ À qualifier
C28: اتفاقية شراكة مع جمعية سوس ماسة تسويق بشأن التمكين الاقتصادي للنساء والشباب في ميدان قطاع الاقتصاد الاجتماعي والتضامني | H28: مرة كل ستة أشهر وكلما دعت الضرورة إلى دلك | U28: =IF(ISNUMBER(T28),IF(T28<TODAY(),"🔴 En retard",IF(T28<=TODAY()+30,"🟠 À déclencher",IF(T28<=TODAY()+60,"🟡 À préparer","🟢 À jour"))),IF(T28<>"","⚪ À surveiller",IF(OR(ISNUMBER(SEARCH("besoin",H28)),ISNUMBER(SEARCH("الضرورة",H28))),"⚪ À surveiller","⚪ À qualifier"))) -> ⚪ À surveiller
C29: اتفاقية شراكة من أجل مواكبة الصناع التقليديين والتعاونيات الحرفية بجهة سوس ماسة في مجال تقوية وتعزيز قدراتهم الحرفية واقتناء المعدات والمواد الأولية | H29: مرة كل شهرين وكاما دعت الضرورة إلى دلك | N29: 46127 | T29: 46204 | U29: =IF(ISNUMBER(T29),IF(T29<TODAY(),"🔴 En retard",IF(T29<=TODAY()+30,"🟠 À déclencher",IF(T29<=TODAY()+60,"🟡 À préparer","🟢 À jour"))),IF(T29<>"","⚪ À surveiller",IF(OR(ISNUMBER(SEARCH("besoin",H29)),ISNUMBER(SEARCH("الضرورة",H29))),"⚪ À surveiller","⚪ À qualifier"))) -> 🔴 En retard
C30: اتفاقية شراكة تتعلق بإحداث مركب حرفي للفخارة بتزنيت | H30: مرة كل ستة أشهر وكلما دعت الضرورة إلى ذلك | N30: 45992 | U30: =IF(ISNUMBER(T30),IF(T30<TODAY(),"🔴 En retard",IF(T30<=TODAY()+30,"🟠 À déclencher",IF(T30<=TODAY()+60,"🟡 À préparer","🟢 À jour"))),IF(T30<>"","⚪ À surveiller",IF(OR(ISNUMBER(SEARCH("besoin",H30)),ISNUMBER(SEARCH("الضرورة",H30))),"⚪ À surveiller","⚪ À qualifier"))) -> ⚪ À surveiller
C31: اتفاقية شراكة من اجل دعـم أنـدية كـرة القـدم بجهة سوس ماسة | H31: مرة واحدة | N31: 44995 | U31: =IF(ISNUMBER(T31),IF(T31<TODAY(),"🔴 En retard",IF(T31<=TODAY()+30,"🟠 À déclencher",IF(T31<=TODAY()+60,"🟡 À préparer","🟢 À jour"))),IF(T31<>"","⚪ À surveiller",IF(OR(ISNUMBER(SEARCH("besoin",H31)),ISNUMBER(SEARCH("الضرورة",H31))),"⚪ À surveiller","⚪ À qualifier"))) -> ⚪ À qualifier
C32: اتفاقية شراكة مع نادي اولامبيك الدشيرة | H32: مرة واحدة | N32: 44994 | U32: =IF(ISNUMBER(T32),IF(T32<TODAY(),"🔴 En retard",IF(T32<=TODAY()+30,"🟠 À déclencher",IF(T32<=TODAY()+60,"🟡 À préparer","🟢 À jour"))),IF(T32<>"","⚪ À surveiller",IF(OR(ISNUMBER(SEARCH("besoin",H32)),ISNUMBER(SEARCH("الضرورة",H32))),"⚪ À surveiller","⚪ À qualifier"))) -> ⚪ À qualifier
C33: اتفاقية مع الإتحاد الرياضي لحسنية أكادير لكرة القدم | H33: مرة واحدة | N33: 44994 | U33: =IF(ISNUMBER(T33),IF(T33<TODAY(),"🔴 En retard",IF(T33<=TODAY()+30,"🟠 À déclencher",IF(T33<=TODAY()+60,"🟡 À préparer","🟢 À jour"))),IF(T33<>"","⚪ À surveiller",IF(OR(ISNUMBER(SEARCH("besoin",H33)),ISNUMBER(SEARCH("الضرورة",H33))),"⚪ À surveiller","⚪ À qualifier"))) -> ⚪ À qualifier
C34: اتفاقية شراكة مع نادي رجاء اكادير لكرة اليد | H34: مرة واحدة | N34: 44995 | U34: =IF(ISNUMBER(T34),IF(T34<TODAY(),"🔴 En retard",IF(T34<=TODAY()+30,"🟠 À déclencher",IF(T34<=TODAY()+60,"🟡 À préparer","🟢 À jour"))),IF(T34<>"","⚪ À surveiller",IF(OR(ISNUMBER(SEARCH("besoin",H34)),ISNUMBER(SEARCH("الضرورة",H34))),"⚪ À surveiller","⚪ À qualifier"))) -> ⚪ À qualifier
C35: اتفاقية شراكة إحداث مركز جامعي في كرة القدم بتارودانت | H35: مرة كل 3 اشهر و كلما دعت الضرورة لدلك | N35: 45987 | T35: 46079 | U35: =IF(ISNUMBER(T35),IF(T35<TODAY(),"🔴 En retard",IF(T35<=TODAY()+30,"🟠 À déclencher",IF(T35<=TODAY()+60,"🟡 À préparer","🟢 À jour"))),IF(T35<>"","⚪ À surveiller",IF(OR(ISNUMBER(SEARCH("besoin",H35)),ISNUMBER(SEARCH("الضرورة",H35))),"⚪ À surveiller","⚪ À qualifier"))) -> 🔴 En retard
C36: اتفاقية شراكة من اجل دعـم أنـدية كـرة القـدم بجهة سوس ماسة | H36: مرة واحدة | U36: =IF(ISNUMBER(T36),IF(T36<TODAY(),"🔴 En retard",IF(T36<=TODAY()+30,"🟠 À déclencher",IF(T36<=TODAY()+60,"🟡 À préparer","🟢 À jour"))),IF(T36<>"","⚪ À surveiller",IF(OR(ISNUMBER(SEARCH("besoin",H36)),ISNUMBER(SEARCH("الضرورة",H36))),"⚪ À surveiller","⚪ À qualifier"))) -> ⚪ À qualifier
C37: اتفاقية شراكة مع نادي اولمبيك الدشيرة | H37: مرة واحدة | U37: =IF(ISNUMBER(T37),IF(T37<TODAY(),"🔴 En retard",IF(T37<=TODAY()+30,"🟠 À déclencher",IF(T37<=TODAY()+60,"🟡 À préparer","🟢 À jour"))),IF(T37<>"","⚪ À surveiller",IF(OR(ISNUMBER(SEARCH("besoin",H37)),ISNUMBER(SEARCH("الضرورة",H37))),"⚪ À surveiller","⚪ À qualifier"))) -> ⚪ À qualifier
C38: اتفاقية مع الإتحاد الرياضي لحسنية أكادير لكرة القدم | H38: مرة واحدة | U38: =IF(ISNUMBER(T38),IF(T38<TODAY(),"🔴 En retard",IF(T38<=TODAY()+30,"🟠 À déclencher",IF(T38<=TODAY()+60,"🟡 À préparer","🟢 À jour"))),IF(T38<>"","⚪ À surveiller",IF(OR(ISNUMBER(SEARCH("besoin",H38)),ISNUMBER(SEARCH("الضرورة",H38))),"⚪ À surveiller","⚪ À qualifier"))) -> ⚪ À qualifier
C39: اتفاقية شراكة مع نادي رجاء اكادير لكرة اليد | H39: مرة واحدة | U39: =IF(ISNUMBER(T39),IF(T39<TODAY(),"🔴 En retard",IF(T39<=TODAY()+30,"🟠 À déclencher",IF(T39<=TODAY()+60,"🟡 À préparer","🟢 À jour"))),IF(T39<>"","⚪ À surveiller",IF(OR(ISNUMBER(SEARCH("besoin",H39)),ISNUMBER(SEARCH("الضرورة",H39))),"⚪ À surveiller","⚪ À qualifier"))) -> ⚪ À qualifier
C40: اتفاقية شراكة مع نادي امل تزنيت لكرة اليد | H40: مرة واحدة | U40: =IF(ISNUMBER(T40),IF(T40<TODAY(),"🔴 En retard",IF(T40<=TODAY()+30,"🟠 À déclencher",IF(T40<=TODAY()+60,"🟡 À préparer","🟢 À jour"))),IF(T40<>"","⚪ À surveiller",IF(OR(ISNUMBER(SEARCH("besoin",H40)),ISNUMBER(SEARCH("الضرورة",H40))),"⚪ À surveiller","⚪ À qualifier"))) -> ⚪ À qualifier
...

Sheet Référentiel
A1: Alerte | B1: Signification | C1: Action type | D1: Horizon
A2: 🔴 En retard | B2: Échéance dépassée | C2: Organiser / régulariser immédiatement | D2: Immédiat
A3: 🟠 À déclencher | B3: Échéance dans 30 jours | C3: Préparer convocation et pièces | D3: 0–30 jours
A4: 🟡 À préparer | B4: Échéance dans 31 à 60 jours | C4: Anticiper avec le responsable | D4: 31–60 jours
A5: 🟢 À jour | B5: Pas d’échéance proche | C5: Aucune action immédiate | D5: > 60 jours
A6: ⚪ À surveiller / qualifier | B6: Pas de date fixe ou règle conditionnelle | C6: Vérifier le déclencheur / la clause | D6: Mensuel
A8: Mise à jour | B8: Contenu | C8: Principe | D8: Source
A9: 16/09/2026 | B9: Intégration du service économique | C9: 123 conventions ajoutées au suivi centralisé | D9: Tableau économique partagé antérieurement
A10: Automatique | B10: Feuille « À faire ce mois » | C10: Se recalcule avec TODAY() à chaque ouverture/recalcul Excel | D10: Formules dynamiques FILTER + statuts
